###  Лабораторна 2a
***
1) Було переглянуто офіційну докуметацію.                       
2) Виконання базових прінтів на Python у файлі new.py  
3) Були створені файли у репозиторію , як на прикладі.      
    **3.i**                     
    Результат виконання команди **python .**      
We are in the __main__                           
2020-10-25 18:29:45.561070                            
linux                         
**3.іі**          
*Команда **python . -h** показує приклад передачі аргументів у Python програму.                                              
*Результат виконання команди **python . -o "Цей текст також має вивестись"**                                             
We are in the __main__                                                         
2020-10-25 18:40:56.447502                                                             
linux                                            
З консолі було передано аргумент                                                           
 ========== >> Цей текст також має вивестись << ==========                                             
 *Результат виконання команди **python . --logs**                                                               
 2020-10-25 18:46:17,252 root INFO: Тут буде просто інформативне повідомлення                                      
 2020-10-25 18:46:17,256 root WARNING: Це Warning повідомлення                      
 2020-10-25 18:46:17,260 root ERROR: Це повідомлення про помилку                                                
 **3.ііi**                               
 Була створена функція у common.py:   
 def func(x):  
     if x:  
         for x in range (0,101,2):  
             print(x, end=" ")  
     else:  
         for x in range (1,100,2)  
 Виклик функції у мейні:    
 print("Вивід моєї функції\n")  
     common.func(False)   
 Результат:  
 We are in the __main__  
 2020-10-26 17:17:26.846380  
 linux  
 Вивід моєї функції  
 1 3 5 7 9 11 13 15 17 19 21 23 25 27 29 31 33 35 37 39 41 43 45 47 49 51 53 55 57 59 61 63 65 67 69 71 73 75 77 79 81 83 85 87 89 91 93 95 97 99       
  **3.iv**  
  Була створена функція ,яка виконується з помилкою.
  У випадку її виникнення виводиться ERROR повідомлення за допомогою логування . 
  Якщо функція відпрацювала без помилки виводиться INFO повідомлення.    
  def func2():  
      keys= {"a":1,"b":2,"c":3,"d":4}  
      try:  
          value =keys['e']  
      except KeyError:  
          logger.error("даного ключа не існує")  
      else:  
          logger.info("ось ваш ключ")  
      finally:  
          print("результат")    
         Результат:    
          2020-10-26 17:56:51,555 root ERROR: даного ключа не існує   
          результат 
                                     
           









